Workbook

Sheet Listas
A1: ⚙️ CONFIGURAÇÕES E LISTAS DE OPÇÕES
A2: Edite as listas abaixo para personalizar todos os dropdowns do sistema. Não altere os cabeçalhos em negrito.
A4: INSTRUMENTOS | B4: ESTÁGIOS | C4: TIPO DE AULA | D4: PRESENÇA | E4: TÉCNICA | F4: PRONTIDÃO CULTO | G4: MÉTODOS / APOSTILAS | H4: HINOS — BÁSICO | I4: HINOS — INTERM. | J4: HINOS — CULTO | K4: PAGAMENTO | L4: STATUS ALUNO | M4: FAIXA ETÁRIA | N4: FÓRMULA / NÃO EDITAR
A5: Piano | B5: Iniciante | C5: Teórica | D5: Presente | E5: Não iniciado | F5: Não avaliado | G5: Faber Vol.1 | H5: Ó Senhor (minha rocha) | I5: Shout to the Lord | J5: Quão Grande és Tu | K5: Pix | L5: Ativo | M5: Musicalização (0-7)
A6: Órgão | B6: Básico | C6: Prática | D6: Falta — Aluno (justificada) | E6: Em andamento | F6: Em preparação | G6: Faber Vol.2 | H6: Grande é o Senhor | I6: Oceans | J6: Aleluia (Leonard Cohen) | K6: Dinheiro | L6: Pausado | M6: Infantil (8-12)
A7: Flauta | B7: Intermediário | C7: Mista | D7: Falta — Aluno (sem aviso) | E7: Concluído | F7: Apto | G7: Faber Vol.3 | H7: Castelo Forte | I7: Good Good Father | J7: How Great is Our God | K7: Transferência | L7: Encerrado | M7: Adolescente (13-17)
A8: Piano e Órgão | B8: Apto — Culto Jovens | C8: Musicalização | D8: Falta — Professora | F8: Não apto no momento | G8: Berens — 100 Estudos | H8: Qual fundamento | I8: Way Maker | J8: Ainda Que a Figueira | K8: Outro | M8: Adulto (18+)
A9: Piano e Flauta | B9: Apto — Culto Adulto | C9: Avaliação | D9: Feriado / Evento | G9: Hanon | I9: 10.000 Reasons | J9: Este é o Dia
B10: Oficializado | G10: Czerny Op.599
G11: Apostila própria — Teoria
G12: Apostila própria — Prática
G13: Hinário CCB
G14: Hinário Batista
G15: Partituras avulsas

Sheet Diário de Aulas
A1: 📖 DIÁRIO DE AULAS
A2: Data | B2: Aluno | C2: Presença | D2: Motivo Ausência | E2: Tipo de Aula | F2: Método(s) Trabalhado(s) | G2: Conteúdo / Repertório | H2: Hino(s) Trabalhado(s) | I2: Lição de Casa | J2: Links de Vídeo Enviados | K2: Avaliação / Observações | L2: Atualizar Progresso?
A3: 45969 | B3: Ana Beatriz Ferreira | C3: Presente | E3: Teórica | F3: Apostila própria — Teoria | G3: Introdução às notas musicais, pauta e claves. Postura ao piano. | I3: Copiar as notas do caderno (pág 3) | K3: Ótima primeira aula, muito atenta. | L3: Não
A4: 45976 | B4: Ana Beatriz Ferreira | C4: Presente | E4: Prática | F4: Faber Vol.1 | G4: Exercícios de posição de mão. Mão direita — Dó maior básico. | H4: Ó Senhor (minha rocha) | I4: Praticar Faber p.4 — 5 min por dia | K4: Mão direita boa. Iniciar mão esquerda na próxima aula. | L4: Não
A5: 45983 | B5: Ana Beatriz Ferreira | C5: Falta — Aluno (justificada) | D5: Viagem família | K5: Reagendada para 25/11. | L5: Não
A6: 45986 | B6: Ana Beatriz Ferreira | C6: Presente | E6: Mista | F6: Faber Vol.1 | G6: Revisão mão direita + introdução mão esquerda. Coordenação básica. | H6: Grande é o Senhor (introdução) | I6: Praticar as duas mãos separadas — Faber p.6 | J6: https://youtu.be/exemplo1 | K6: Progresso rápido. Coordenação melhorando. | L6: Sim
A7: 45997 | B7: Ana Beatriz Ferreira | C7: Presente | E7: Mista | F7: Faber Vol.1 | G7: Duas mãos juntas pela primeira vez — compassos 1-4. | H7: Grande é o Senhor (mão direita completa) | I7: Tocar compassos 1-4 com metrônomo 60 bpm | K7: Dificuldade inicial, mas finalizou os 4 compassos. | L7: Não
A8: 45840 | B8: Lucas Mendes Oliveira | C8: Presente | E8: Teórica | F8: Apostila própria — Teoria | G8: Revisão geral: figuras, compassos, leitura de clave de sol e fá. | I8: Exercícios de teoria — pág 8 a 10 | K8: Base teórica sólida. Avançar para repertório gospel. | L8: Não
A9: 45847 | B9: Lucas Mendes Oliveira | C9: Presente | E9: Prática | F9: Faber Vol.2 | G9: Faber Vol.2 p.12 — exercícios de oitavas e arpejo. | H9: Shout to the Lord (introdução) | I9: Faber p.12-14 + primeiros acordes do hino | J9: https://youtu.be/exemplo2 | K9: Evolução excelente. Arpejo fluindo bem. | L9: Não
A10: 45875 | B10: Lucas Mendes Oliveira | C10: Presente | E10: Mista | F10: Faber Vol.2 | G10: Duas mãos em peça gospel. Introdução à pedaleira — posição dos pés. | H10: Way Maker (completo mão direita) | I10: Praticar pedaleira sozinha — notas básicas | J10: https://youtu.be/exemplo3 | K10: Primeira vez com pedaleira. Concentração boa. | L10: Sim
A11: 45903 | B11: Lucas Mendes Oliveira | C11: Falta — Professora | D11: Compromisso da professora | K11: Aula cancelada pela professora. Reagendada. | L11: Não
A12: 45931 | B12: Lucas Mendes Oliveira | C12: Presente | E12: Mista | F12: Faber Vol.2 + Hinário CCB | G12: Repertório para culto jovens. Revisão técnica e postura. | H12: Way Maker + Good Good Father | I12: Gravar vídeo tocando Way Maker | K12: Aprovado para culto jovens. Agendar avaliação. | L12: Sim
A13: 45601 | B13: Fernanda Costa | C13: Presente | E13: Teórica | F13: Apostila própria — Teoria | G13: Retomada: leitura de partituras, fórmulas de compasso. | I13: Exercícios de leitura — pág 1 a 5 | K13: Segunda experiência. Lembrou bastante coisa. | L13: Não
A14: 45636 | B14: Fernanda Costa | C14: Presente | E14: Prática | F14: Czerny Op.599 | G14: Czerny Op.599 n.1 e n.2. Foco em independência de dedos. | H14: Quão Grande és Tu (introdução) | I14: Czerny n.1 e 2 — 10 min/dia | J14: https://youtu.be/exemplo4 | K14: Técnica precisa de trabalho. Perseverança ótima. | L14: Não
A15: 45692 | B15: Fernanda Costa | C15: Presente | E15: Mista | F15: Czerny Op.599 + Apostila própria — Prática | G15: Duas mãos em Czerny n.5. Iniciando hinos com cifra. | H15: 10.000 Reasons (acordes básicos) | I15: Czerny n.5 + cifra do hino mão direita | J15: https://youtu.be/exemplo5 | K15: Progresso consistente. Harmonia melhorando. | L15: Sim
A16: 45748 | B16: Fernanda Costa | C16: Presente | E16: Mista | F16: Czerny Op.599 | G16: Peças completas com duas mãos. Iniciando ornamentação. | H16: Quão Grande és Tu (completo) | I16: Tocar Czerny n.8 fluente | K16: Pronta para avaliação de culto em breve. | L16: Sim
A17: 45783 | B17: Fernanda Costa | C17: Falta — Aluno (sem aviso) | K17: Não compareceu. Sem justificativa até o momento. | L17: Não
A18: 46032 | B18: Isabela Rocha Santos | C18: Presente | E18: Musicalização | F18: Apostila própria — Prática | G18: Reconhecimento de sons (agudo/grave). Imitação rítmica com palmas. | I18: Ouvir e identificar sons em casa | K18: Primeira aula. Criança muito participativa! | L18: Não
A19: 46039 | B19: Isabela Rocha Santos | C19: Presente | E19: Musicalização | F19: Apostila própria — Prática | G19: Introdução à flauta — postura e sopro básico. Notas Si e Lá. | I19: Soprar a flauta 5 min por dia | J19: https://youtu.be/exemplo6 | K19: Encantada com o instrumento. Sopro já firme. | L19: Não
A20: 46060 | B20: Isabela Rocha Santos | C20: Presente | E20: Musicalização | F20: Apostila própria — Prática | G20: Notas Sol, Fá, Mi na flauta. Primeira melodia simples. | I20: Praticar escala de Dó na flauta | K20: Progresso rápido para a idade. Muito musical. | L20: Sim
A21: 46088 | B21: Isabela Rocha Santos | C21: Falta — Aluno (justificada) | D21: Doença | K21: Responsável avisou com antecedência. Reagendada. | L21: Não
A22: 45784 | B22: Rafael Almeida | C22: Presente | E22: Mista | F22: Hanon + Hinário Batista | G22: Exercícios de velocidade Hanon n.1-5. Revisão de repertório gospel. | H22: Ainda Que a Figueira (completo) | I22: Hanon n.6 e 7 — 120 bpm | K22: Técnica avançada. Velocidade precisa de trabalho. | L22: Não
A23: 45840 | B23: Rafael Almeida | C23: Presente | E23: Prática | F23: Hanon + Berens — 100 Estudos | G23: Berens 20-25. Passagem para órgão — pedaleira com harmonia. | H23: How Great is Our God (órgão + pedal) | I23: Berens 26 + pedaleira com baixo pedal | J23: https://youtu.be/exemplo7 | K23: Pedaleira evoluindo muito. Som cheio no órgão. | L23: Sim
A24: 45903 | B24: Rafael Almeida | C24: Presente | E24: Avaliação | F24: Partituras avulsas | G24: Avaliação formal: 3 hinos completos, leitura à primeira vista. | H24: Quão Grande és Tu + How Great is Our God + Este é o Dia | I24: Preparar set de 4 hinos para culto adulto | K24: APROVADO para culto adulto. Excelente avaliação! | L24: Sim
A25: 45966 | B25: Rafael Almeida | C25: Presente | E25: Mista | F25: Berens — 100 Estudos | G25: Refinamento técnico. Preparação para oficialização. | H25: Aleluia (Leonard Cohen arr. gospel) + Oceans | I25: Repertório completo de oficialização — 5 hinos | J25: https://youtu.be/exemplo8 | K25: Candidato forte para oficialização. Data a definir. | L25: Sim

Sheet Alunos
A1: 🎵 CADASTRO DE ALUNOS
A2: ID | B2: Nome Completo | C2: Data Nascimento | D2: Faixa Etária | E2: Instrumento(s) | F2: Contato (WhatsApp) | G2: Responsável (se menor) | H2: Horário Semanal | I2: Valor Mensalidade (R$) | J2: Data Início | K2: Meses Ativos | L2: Status | M2: Observações
A3: 1 | B3: Ana Beatriz Ferreira | C3: 40252 | D3: =IF(AND(Alunos!C3<>"",Alunos!C3<>0),IF(DATEDIF(C3,TODAY(),"Y")<8,"Musicalização (0-7)",IF(DATEDIF(C3,TODAY(),"Y")<13,"Infantil (8-12)",IF(DATEDIF(C3,TODAY(),"Y")<18,"Adolescente (13-17)","Adulto (18+)"))),"—") -> Adolescente (13-17) | E3: Piano | F3: (11) 98765-4321 | G3: Maria Ferreira | H3: Sábado 09:00 | I3: 180 | J3: 45962 | K3: =DATEDIF(J3,TODAY(),"M") -> 6 | L3: Ativo | M3: Muito dedicada. Boa leitura de partitura. Objetivo: tocar no culto jovens.
A4: 2 | B4: Lucas Mendes Oliveira | C4: 39651 | D4: =IF(AND(Alunos!C4<>"",Alunos!C4<>0),IF(DATEDIF(C4,TODAY(),"Y")<8,"Musicalização (0-7)",IF(DATEDIF(C4,TODAY(),"Y")<13,"Infantil (8-12)",IF(DATEDIF(C4,TODAY(),"Y")<18,"Adolescente (13-17)","Adulto (18+)"))),"—") -> Adolescente (13-17) | E4: Piano e Órgão | F4: (11) 97654-3210 | G4: Carlos Mendes | H4: Quarta 17:00 | I4: 200 | J4: 45839 | K4: =DATEDIF(J4,TODAY(),"M") -> 10 | L4: Ativo | M4: Adolescente, aprende rápido. Já praticando com duas mãos. Meta: culto adulto.
A5: 3 | B5: Fernanda Costa | C5: 32903 | D5: =IF(AND(Alunos!C5<>"",Alunos!C5<>0),IF(DATEDIF(C5,TODAY(),"Y")<8,"Musicalização (0-7)",IF(DATEDIF(C5,TODAY(),"Y")<13,"Infantil (8-12)",IF(DATEDIF(C5,TODAY(),"Y")<18,"Adolescente (13-17)","Adulto (18+)"))),"—") -> Adulto (18+) | E5: Piano | F5: (11) 96543-2109 | H5: Terça 19:00 | I5: 220 | J5: 45597 | K5: =DATEDIF(J5,TODAY(),"M") -> 18 | L5: Ativo | M5: Adulta, segunda experiência com piano. Progresso sólido em teoria.
A6: 4 | B6: Isabela Rocha Santos | C6: 43348 | D6: =IF(AND(Alunos!C6<>"",Alunos!C6<>0),IF(DATEDIF(C6,TODAY(),"Y")<8,"Musicalização (0-7)",IF(DATEDIF(C6,TODAY(),"Y")<13,"Infantil (8-12)",IF(DATEDIF(C6,TODAY(),"Y")<18,"Adolescente (13-17)","Adulto (18+)"))),"—") -> Musicalização (0-7) | E6: Flauta | F6: (11) 95432-1098 | G6: Sandra Rocha | H6: Sábado 10:00 | I6: 150 | J6: 46023 | K6: =DATEDIF(J6,TODAY(),"M") -> 4 | L6: Ativo | M6: Musicalização infantil. Foco em ritmo e percepção. Muito animada.
A7: 5 | B7: Rafael Almeida | C7: 36999 | D7: =IF(AND(Alunos!C7<>"",Alunos!C7<>0),IF(DATEDIF(C7,TODAY(),"Y")<8,"Musicalização (0-7)",IF(DATEDIF(C7,TODAY(),"Y")<13,"Infantil (8-12)",IF(DATEDIF(C7,TODAY(),"Y")<18,"Adolescente (13-17)","Adulto (18+)"))),"—") -> Adulto (18+) | E7: Piano e Órgão | F7: (11) 94321-0987 | H7: Quinta 18:30 | I7: 240 | J7: 45778 | K7: =DATEDIF(J7,TODAY(),"M") -> 12 | L7: Ativo | M7: Adulto jovem. Já em nível intermediário. Candidato a oficial no culto adulto.

Sheet Financeiro
A1: 💰 CONTROLE FINANCEIRO — MENSALIDADES
A2: Mês/Ano Ref. | B2: Aluno | C2: Valor Cobrado (R$) | D2: Valor Pago (R$) | E2: Status | F2: Data Pagamento | G2: Forma Pagamento | H2: Desconto/Obs | I2: Saldo (R$)
A3: 11/2025 | B3: Ana Beatriz Ferreira | C3: 180 | D3: 180 | E3: Pago | F3: 45966 | G3: Pix | I3: =D3-C3 -> 0
A4: 12/2025 | B4: Ana Beatriz Ferreira | C4: 180 | D4: 180 | E4: Pago | F4: 45994 | G4: Pix | I4: =D4-C4 -> 0
A5: 01/2026 | B5: Ana Beatriz Ferreira | C5: 180 | D5: 180 | E5: Pago | F5: 46032 | G5: Pix | I5: =D5-C5 -> 0
A6: 02/2026 | B6: Ana Beatriz Ferreira | C6: 180 | D6: 180 | E6: Pago | F6: 46060 | G6: Dinheiro | I6: =D6-C6 -> 0
A7: 03/2026 | B7: Ana Beatriz Ferreira | C7: 180 | D7: 180 | E7: Pago | F7: 46084 | G7: Pix | I7: =D7-C7 -> 0
A8: 04/2026 | B8: Ana Beatriz Ferreira | C8: 180 | D8: 180 | E8: Pago | F8: 46119 | G8: Pix | I8: =D8-C8 -> 0
A9: 05/2026 | B9: Ana Beatriz Ferreira | C9: 180 | E9: Pendente | I9: =D9-C9 -> -180
A10: 07/2025 | B10: Lucas Mendes Oliveira | C10: 200 | D10: 200 | E10: Pago | F10: 45843 | G10: Dinheiro | I10: =D10-C10 -> 0
A11: 08/2025 | B11: Lucas Mendes Oliveira | C11: 200 | D11: 200 | E11: Pago | F11: 45872 | G11: Pix | I11: =D11-C11 -> 0
A12: 09/2025 | B12: Lucas Mendes Oliveira | C12: 200 | D12: 200 | E12: Pago | F12: 45905 | G12: Pix | I12: =D12-C12 -> 0
A13: 10/2025 | B13: Lucas Mendes Oliveira | C13: 200 | D13: 200 | E13: Pago | F13: 45938 | G13: Pix | I13: =D13-C13 -> 0
A14: 11/2025 | B14: Lucas Mendes Oliveira | C14: 200 | D14: 200 | E14: Pago | F14: 45969 | G14: Dinheiro | I14: =D14-C14 -> 0
A15: 12/2025 | B15: Lucas Mendes Oliveira | C15: 200 | D15: 200 | E15: Pago | F15: 46001 | G15: Pix | I15: =D15-C15 -> 0
A16: 01/2026 | B16: Lucas Mendes Oliveira | C16: 200 | D16: 200 | E16: Pago | F16: 46032 | G16: Pix | I16: =D16-C16 -> 0
A17: 02/2026 | B17: Lucas Mendes Oliveira | C17: 200 | D17: 200 | E17: Pago | F17: 46061 | G17: Dinheiro | I17: =D17-C17 -> 0
A18: 03/2026 | B18: Lucas Mendes Oliveira | C18: 200 | D18: 200 | E18: Pago | F18: 46091 | G18: Dinheiro | I18: =D18-C18 -> 0
A19: 04/2026 | B19: Lucas Mendes Oliveira | C19: 200 | D19: 200 | E19: Pago | F19: 46119 | G19: Pix | I19: =D19-C19 -> 0
A20: 05/2026 | B20: Lucas Mendes Oliveira | C20: 200 | E20: Pendente | I20: =D20-C20 -> -200
A21: 11/2024 | B21: Fernanda Costa | C21: 220 | D21: 220 | E21: Pago | F21: 45601 | G21: Pix | I21: =D21-C21 -> 0
A22: 12/2024 | B22: Fernanda Costa | C22: 220 | D22: 220 | E22: Pago | F22: 45633 | G22: Pix | I22: =D22-C22 -> 0
A23: 01/2025 | B23: Fernanda Costa | C23: 220 | D23: 220 | E23: Pago | F23: 45664 | G23: Dinheiro | I23: =D23-C23 -> 0
A24: 02/2025 | B24: Fernanda Costa | C24: 220 | D24: 220 | E24: Pago | F24: 45696 | G24: Pix | I24: =D24-C24 -> 0
A25: 03/2025 | B25: Fernanda Costa | C25: 220 | D25: 220 | E25: Pago | F25: 45721 | G25: Pix | I25: =D25-C25 -> 0
A26: 04/2025 | B26: Fernanda Costa | C26: 220 | D26: 220 | E26: Pago | F26: 45752 | G26: Pix | I26: =D26-C26 -> 0
A27: 05/2025 | B27: Fernanda Costa | C27: 220 | D27: 220 | E27: Pago | F27: 45785 | G27: Pix | I27: =D27-C27 -> 0
A28: 06/2025 | B28: Fernanda Costa | C28: 220 | D28: 220 | E28: Pago | F28: 45815 | G28: Dinheiro | I28: =D28-C28 -> 0
A29: 07/2025 | B29: Fernanda Costa | C29: 220 | D29: 220 | E29: Pago | F29: 45848 | G29: Dinheiro | I29: =D29-C29 -> 0
A30: 08/2025 | B30: Fernanda Costa | C30: 220 | D30: 220 | E30: Pago | F30: 45877 | G30: Pix | I30: =D30-C30 -> 0
A31: 09/2025 | B31: Fernanda Costa | C31: 220 | D31: 220 | E31: Pago | F31: 45908 | G31: Pix | I31: =D31-C31 -> 0
A32: 10/2025 | B32: Fernanda Costa | C32: 220 | D32: 220 | E32: Pago | F32: 45938 | G32: Dinheiro | I32: =D32-C32 -> 0
... A37: 03/2026 | B37: Fernanda Costa | C37: 220 | D37: 220 | E37: Pago | F37: 46091 | G37: Pix | I37: =D37-C37 -> 0
A38: 04/2026 | B38: Fernanda Costa | C38: 220 | E38: Pendente | H38: Avisou que paga até dia 10 | I38: =D38-C38 -> -220
A39: 05/2026 | B39: Fernanda Costa | C39: 220 | E39: Pendente | I39: =D39-C39 -> -220
A40: 01/2026 | B40: Isabela Rocha Santos | C40: 150 | D40: 150 | E40: Pago | F40: 46029 | G40: Pix | I40: =D40-C40 -> 0
A41: 02/2026 | B41: Isabela Rocha Santos | C41: 150 | D41: 150 | E41: Pago | F41: 46063 | G41: Dinheiro | I41: =D41-C41 -> 0
A42: 03/2026 | B42: Isabela Rocha Santos | C42: 150 | D42: 150 | E42: Pago | F42: 46089 | G42: Pix | I42: =D42-C42 -> 0
A43: 04/2026 | B43: Isabela Rocha Santos | C43: 150 | D43: 150 | E43: Pago | F43: 46115 | G43: Pix | I43: =D43-C43 -> 0
A44: 05/2026 | B44: Isabela Rocha Santos | C44: 150 | E44: Pendente | I44: =D44-C44 -> -150
...

Sheet Progresso
A1: 📈 PROGRESSO POR ALUNO
A2: Aluno | B2: Instrumento | C2: Estágio Atual | D2: Teoria (0-100%) | E2: Método Atual | F2: Página/Lição Atual | G2: Técnica — 1 Mão | H2: Técnica — 2 Mãos | I2: Técnica — Pedaleira | J2: Hinos Dominados (qtd) | K2: Lista de Hinos | L2: Culto Jovens | M2: Culto Adulto | N2: Oficialização | O2: Última Atualização | P2: Obs. da Professora
A3: Ana Beatriz Ferreira | B3: Piano | C3: Básico | D3: 0.25 | E3: Faber Vol.1 | F3: p. 6 | G3: Concluído | H3: Em andamento | I3: Não iniciado | J3: 2 | K3: Grande é o Senhor, Ó Senhor (minha rocha) | L3: Em preparação | M3: Não avaliado | N3: Não avaliado | O3: 45997 | P3: Evolução constante. Coordenação das duas mãos em desenvolvimento.
A4: Lucas Mendes Oliveira | B4: Piano e Órgão | C4: Apto — Culto Jovens | D4: 0.7 | E4: Faber Vol.2 | F4: p. 18 | G4: Concluído | H4: Concluído | I4: Em andamento | J4: 5 | K4: Way Maker, Good Good Father, Shout to the Lord, 10.000 Reasons, Oceans | L4: Apto | M4: Em preparação | N4: Não avaliado | O4: 45931 | P4: Aprovado culto jovens. Pedaleira em progresso para culto adulto.
A5: Fernanda Costa | B5: Piano | C5: Intermediário | D5: 0.6 | E5: Czerny Op.599 | F5: n. 8 | G5: Concluído | H5: Concluído | I5: Não iniciado | J5: 4 | K5: Quão Grande és Tu, 10.000 Reasons, Ainda Que a Figueira, How Great is Our God | L5: Em preparação | M5: Em preparação | N5: Não avaliado | O5: 45748 | P5: Pronta para avaliação de culto. Foco em performance e fluidez.
A6: Isabela Rocha Santos | B6: Flauta | C6: Iniciante | D6: 0.1 | E6: Apostila própria — Prática | F6: Módulo 2 | G6: Em andamento | H6: Não iniciado | I6: Não iniciado | J6: 0 | K6: — | L6: Não avaliado | M6: Não avaliado | N6: Não avaliado | O6: 46060 | P6: Musicalização em andamento. Foco em percepção e técnica básica de flauta.
A7: Rafael Almeida | B7: Piano e Órgão | C7: Apto — Culto Adulto | D7: 0.88 | E7: Berens — 100 Estudos | F7: Est. 28 | G7: Concluído | H7: Concluído | I7: Concluído | J7: 8 | K7: Quão Grande és Tu, How Great is Our God, Este é o Dia, Aleluia, Oceans, Way Maker, Ainda Que a Figueira, 10.000 Reasons | L7: Apto | M7: Apto | N7: Em preparação | O7: 45966 | P7: Candidato à oficialização. Refinamento técnico em andamento.

Sheet Dashboard
A1: 🎼 DASHBOARD — VISÃO GERAL
A2: Atualizado automaticamente via fórmulas • Referência: 23/05/2026
A4: Total de Alunos Ativos | C4: Aulas Este Mês | E4: Faltas Este Mês | G4: Receita Mês Atual (R$) | I4: Pendências (R$)
A5: =COUNTIF(Alunos!L3:L100,"Ativo") -> 5 | C5: =COUNTIFS('Diário de Aulas'!A3:A500,">="&DATE(YEAR(TODAY()),MONTH(TODAY()),1),'Diário de Aulas'!A3:A500,"<="&EOMONTH(TODAY(),0),'Diário de Aulas'!C3:C500,"Presente") -> 0 | E5: =COUNTIFS('Diário de Aulas'!A3:A500,">="&DATE(YEAR(TODAY()),MONTH(TODAY()),1),'Diário de Aulas'!A3:A500,"<="&EOMONTH(TODAY(),0),'Diário de Aulas'!C3:C500,"<>Presente",'Diário de Aulas'!C3:C500,"<>") -> 0 | G5: =SUMIFS(Financeiro!C3:C57,Financeiro!E3:E57,"Pago",Financeiro!A3:A57,TEXT(TODAY(),"mm/yyyy")) -> 0 | I5: =SUMIF(Financeiro!E3:E57,"Pendente",Financeiro!C3:C57) -> 1210
A8: DISTRIBUIÇÃO POR ESTÁGIO | G8: PRONTIDÃO PARA CULTO
A9: Iniciante | B9: =COUNTIF(Progresso!C3:C100,"Iniciante") -> 1 | C9: =IF(COUNTIF(Alunos!L:L,"Ativo")>0,COUNTIF(Progresso!C3:C100,"Iniciante")/COUNTIF(Alunos!L:L,"Ativo"),0) -> 0.2 | G9: Culto Jovens | I9: =COUNTIF(Progresso!L3:L100,"Apto") -> 2 | J9: alunos aptos
A10: Básico | B10: =COUNTIF(Progresso!C3:C100,"Básico") -> 1 | C10: =IF(COUNTIF(Alunos!L:L,"Ativo")>0,COUNTIF(Progresso!C3:C100,"Básico")/COUNTIF(Alunos!L:L,"Ativo"),0) -> 0.2 | G10: Culto Adulto | I10: =COUNTIF(Progresso!M3:M100,"Apto") -> 1 | J10: alunos aptos
A11: Intermediário | B11: =COUNTIF(Progresso!C3:C100,"Intermediário") -> 1 | C11: =IF(COUNTIF(Alunos!L:L,"Ativo")>0,COUNTIF(Progresso!C3:C100,"Intermediário")/COUNTIF(Alunos!L:L,"Ativo"),0) -> 0.2 | G11: Oficialização | I11: =COUNTIF(Progresso!N3:N100,"Apto") -> 0 | J11: alunos aptos
A12: Apto Jovens | B12: =COUNTIF(Progresso!C3:C100,"Apto — Culto Jovens") -> 1 | C12: =IF(COUNTIF(Alunos!L:L,"Ativo")>0,COUNTIF(Progresso!C3:C100,"Apto — Culto Jovens")/COUNTIF(Alunos!L:L,"Ativo"),0) -> 0.2
A13: Apto Adulto | B13: =COUNTIF(Progresso!C3:C100,"Apto — Culto Adulto") -> 1 | C13: =IF(COUNTIF(Alunos!L:L,"Ativo")>0,COUNTIF(Progresso!C3:C100,"Apto — Culto Adulto")/COUNTIF(Alunos!L:L,"Ativo"),0) -> 0.2
A14: Oficializado | B14: =COUNTIF(Progresso!C3:C100,"Oficializado") -> 0 | C14: =IF(COUNTIF(Alunos!L:L,"Ativo")>0,COUNTIF(Progresso!C3:C100,"Oficializado")/COUNTIF(Alunos!L:L,"Ativo"),0) -> 0
A16: FREQUÊNCIA POR ALUNO — ÚLTIMAS 4 SEMANAS
A17: Aluno | B17: Aulas Prev. | C17: Presenças | D17: Faltas | E17: Taxa Freq. | F17: Status
A18: Ana Beatriz Ferreira | B18: =C18+D18 -> 0 | C18: =COUNTIFS('Diário de Aulas'!B3:B500,"Ana Beatriz Ferreira",'Diário de Aulas'!A3:A500,">="&TODAY()-28,'Diário de Aulas'!C3:C500,"Presente") -> 0 | D18: =COUNTIFS('Diário de Aulas'!B3:B500,"Ana Beatriz Ferreira",'Diário de Aulas'!A3:A500,">="&TODAY()-28,'Diário de Aulas'!C3:C500,"<>Presente",'Diário de Aulas'!C3:C500,"<>") -> 0 | E18: =IF(B18>0,C18/B18,0) -> 0 | F18: =IF(E18>=0.8,"Regular",IF(E18>=0.5,"Atenção","Irregular")) -> Irregular
A19: Lucas Mendes Oliveira | B19: =C19+D19 -> 0 | C19: =COUNTIFS('Diário de Aulas'!B3:B500,"Lucas Mendes Oliveira",'Diário de Aulas'!A3:A500,">="&TODAY()-28,'Diário de Aulas'!C3:C500,"Presente") -> 0 | D19: =COUNTIFS('Diário de Aulas'!B3:B500,"Lucas Mendes Oliveira",'Diário de Aulas'!A3:A500,">="&TODAY()-28,'Diário de Aulas'!C3:C500,"<>Presente",'Diário de Aulas'!C3:C500,"<>") -> 0 | E19: =IF(B19>0,C19/B19,0) -> 0 | F19: =IF(E19>=0.8,"Regular",IF(E19>=0.5,"Atenção","Irregular")) -> Irregular
A20: Fernanda Costa | B20: =C20+D20 -> 0 | C20: =COUNTIFS('Diário de Aulas'!B3:B500,"Fernanda Costa",'Diário de Aulas'!A3:A500,">="&TODAY()-28,'Diário de Aulas'!C3:C500,"Presente") -> 0 | D20: =COUNTIFS('Diário de Aulas'!B3:B500,"Fernanda Costa",'Diário de Aulas'!A3:A500,">="&TODAY()-28,'Diário de Aulas'!C3:C500,"<>Presente",'Diário de Aulas'!C3:C500,"<>") -> 0 | E20: =IF(B20>0,C20/B20,0) -> 0 | F20: =IF(E20>=0.8,"Regular",IF(E20>=0.5,"Atenção","Irregular")) -> Irregular
A21: Isabela Rocha Santos | B21: =C21+D21 -> 0 | C21: =COUNTIFS('Diário de Aulas'!B3:B500,"Isabela Rocha Santos",'Diário de Aulas'!A3:A500,">="&TODAY()-28,'Diário de Aulas'!C3:C500,"Presente") -> 0 | D21: =COUNTIFS('Diário de Aulas'!B3:B500,"Isabela Rocha Santos",'Diário de Aulas'!A3:A500,">="&TODAY()-28,'Diário de Aulas'!C3:C500,"<>Presente",'Diário de Aulas'!C3:C500,"<>") -> 0 | E21: =IF(B21>0,C21/B21,0) -> 0 | F21: =IF(E21>=0.8,"Regular",IF(E21>=0.5,"Atenção","Irregular")) -> Irregular
A22: Rafael Almeida | B22: =C22+D22 -> 0 | C22: =COUNTIFS('Diário de Aulas'!B3:B500,"Rafael Almeida",'Diário de Aulas'!A3:A500,">="&TODAY()-28,'Diário de Aulas'!C3:C500,"Presente") -> 0 | D22: =COUNTIFS('Diário de Aulas'!B3:B500,"Rafael Almeida",'Diário de Aulas'!A3:A500,">="&TODAY()-28,'Diário de Aulas'!C3:C500,"<>Presente",'Diário de Aulas'!C3:C500,"<>") -> 0 | E22: =IF(B22>0,C22/B22,0) -> 0 | F22: =IF(E22>=0.8,"Regular",IF(E22>=0.5,"Atenção","Irregular")) -> Irregular
